[25/Sep/2018 17:33:52] ERROR [django.request:228] Internal Server Error: /
Traceback (most recent call last):
  File "C:\Users\JOJO-NTIAMOAH\.virtualenvs\Dmznum-jav2mAZD\lib\site-packages\django\core\handlers\exception.py", line 34, in inner
    response = get_response(request)
  File "C:\Users\JOJO-NTIAMOAH\.virtualenvs\Dmznum-jav2mAZD\lib\site-packages\django\core\handlers\base.py", line 126, in _get_response
    response = self.process_exception_by_middleware(e, request)
  File "C:\Users\JOJO-NTIAMOAH\.virtualenvs\Dmznum-jav2mAZD\lib\site-packages\django\core\handlers\base.py", line 124, in _get_response
    response = wrapped_callback(request, *callback_args, **callback_kwargs)
  File "C:\dz\Dmznum\damzi\views.py", line 7, in index
    return render_to_response('damzi/index.html')
  File "C:\Users\JOJO-NTIAMOAH\.virtualenvs\Dmznum-jav2mAZD\lib\site-packages\django\shortcuts.py", line 27, in render_to_response
    content = loader.render_to_string(template_name, context, using=using)
  File "C:\Users\JOJO-NTIAMOAH\.virtualenvs\Dmznum-jav2mAZD\lib\site-packages\django\template\loader.py", line 62, in render_to_string
    return template.render(context, request)
  File "C:\Users\JOJO-NTIAMOAH\.virtualenvs\Dmznum-jav2mAZD\lib\site-packages\django\template\backends\django.py", line 61, in render
    return self.template.render(context)
  File "C:\Users\JOJO-NTIAMOAH\.virtualenvs\Dmznum-jav2mAZD\lib\site-packages\django\template\base.py", line 171, in render
    return self._render(context)
  File "C:\Users\JOJO-NTIAMOAH\.virtualenvs\Dmznum-jav2mAZD\lib\site-packages\django\template\base.py", line 163, in _render
    return self.nodelist.render(context)
  File "C:\Users\JOJO-NTIAMOAH\.virtualenvs\Dmznum-jav2mAZD\lib\site-packages\django\template\base.py", line 937, in render
    bit = node.render_annotated(context)
  File "C:\Users\JOJO-NTIAMOAH\.virtualenvs\Dmznum-jav2mAZD\lib\site-packages\django\template\base.py", line 904, in render_annotated
    return self.render(context)
  File "C:\Users\JOJO-NTIAMOAH\.virtualenvs\Dmznum-jav2mAZD\lib\site-packages\django\templatetags\static.py", line 106, in render
    url = self.url(context)
  File "C:\Users\JOJO-NTIAMOAH\.virtualenvs\Dmznum-jav2mAZD\lib\site-packages\django\templatetags\static.py", line 103, in url
    return self.handle_simple(path)
  File "C:\Users\JOJO-NTIAMOAH\.virtualenvs\Dmznum-jav2mAZD\lib\site-packages\django\templatetags\static.py", line 118, in handle_simple
    return staticfiles_storage.url(path)
  File "C:\Users\JOJO-NTIAMOAH\.virtualenvs\Dmznum-jav2mAZD\lib\site-packages\django\contrib\staticfiles\storage.py", line 152, in url
    return self._url(self.stored_name, name, force)
  File "C:\Users\JOJO-NTIAMOAH\.virtualenvs\Dmznum-jav2mAZD\lib\site-packages\django\contrib\staticfiles\storage.py", line 131, in _url
    hashed_name = hashed_name_func(*args)
  File "C:\Users\JOJO-NTIAMOAH\.virtualenvs\Dmznum-jav2mAZD\lib\site-packages\django\contrib\staticfiles\storage.py", line 419, in stored_name
    raise ValueError("Missing staticfiles manifest entry for '%s'" % clean_name)
ValueError: Missing staticfiles manifest entry for 'damzi/css/compiled.min.css'
[25/Sep/2018 17:33:53] ERROR [django.server:124] "GET / HTTP/1.1" 500 27
